<?xml version="1.0" ?>
<testsuite errors="1" failures="0" name="CheckOpiFormat-20171122103939" tests="3" time="0.000">
	<testcase classname="CheckOpiFormat" name="test_GIVEN_an_opi_file_with_grouping_containers_WHEN_checking_the_background_colour_THEN_it_is_the_isis_background" time="0.000"/>
	<testcase classname="CheckOpiFormat" name="test_GIVEN_an_opi_file_with_textbox_WHEN_checking_background_colour_THEN_it_is_the_isis_textbox_background" time="0.000"/>
	<testcase classname="CheckOpiFormat" name="test_GIVEN_an_opi_file_with_labels_WHEN_checking_the_background_colour_THEN_it_is_the_isis_background" time="0.000">
		<error message="On line 1042, text '$(NAME)', background colour was not correct." type="AssertionError">
<![CDATA[Traceback (most recent call last):
  File "check_opi_format.py", line 337, in test_GIVEN_an_opi_file_with_labels_WHEN_checking_the_background_colour_THEN_it_is_the_isis_background
    self._assert_background_colour_correct("Label", ["ISIS_Label_Background", "ISIS_Title_Background_NEW"])
  File "check_opi_format.py", line 324, in _assert_background_colour_correct
    ["On line {}, text '{}', background colour was not correct.".format(*error) for error in errors]))
AssertionError: On line 1042, text '$(NAME)', background colour was not correct.
]]>		</error>
	</testcase>
	<system-out>
<![CDATA[]]>	</system-out>
	<system-err>
<![CDATA[]]>	</system-err>
</testsuite>
